Error in sys.excepthook:
Traceback (most recent call last):
  File "/Library/Frameworks/Python.framework/Versions/3.11/lib/python3.11/site-packages/humbug/report.py", line 505, in _hook
    self.error_report(error=exception_instance, tags=tags, publish=publish)
  File "/Library/Frameworks/Python.framework/Versions/3.11/lib/python3.11/site-packages/humbug/report.py", line 247, in error_report
    traceback.format_exception(
TypeError: format_exception() got an unexpected keyword argument 'etype'

Original exception was:
Traceback (most recent call last):
  File "/Users/defalt/Desktop/Athena/research/swarms/groupchat.py", line 23, in <module>
    response = chat.run("Captain Price", "Hello, how are you John?")
               ^^^^^^^^^^^^^^^^^^^^^^^^^^^^^^^^^^^^^^^^^^^^^^^^^^^^^
  File "/Users/defalt/Desktop/Athena/research/swarms/swarms/swarms/groupchat.py", line 60, in run
    responses[agent_name] = agent.run(message)
                            ^^^^^^^^^^^^^^^^^^
  File "/Users/defalt/Desktop/Athena/research/swarms/swarms/agents/simple_agent.py", line 35, in run
    response = self.flow.run(task)
               ^^^^^^^^^^^^^^^^^^^
  File "/Users/defalt/Desktop/Athena/research/swarms/swarms/structs/flow.py", line 151, in run
    if self.dashboard:
       ^^^^^^^^^^^^^^
AttributeError: 'Flow' object has no attribute 'dashboard'
